<?xml version="1.0" encoding="utf-8"?>
<!-- This URDF was automatically created by SolidWorks to URDF Exporter! Originally created by Stephen Brawner (brawner@gmail.com) 
     Commit Version: 1.6.0-1-g15f4949  Build Version: 1.6.7594.29634
     For more information, please see http://wiki.ros.org/sw_urdf_exporter -->
<robot
  name="linkage_urdf">
  <link name="baselink"/>
  <joint name="floating_base" type="floating">
    <!-- <origin rpy="0 0 0" xyz="0 0 0.725000"/> -->
    <origin rpy="0 0 0" xyz="0 0 0"/>
    <parent link="baselink"/>
    <child link="torso"/>
  </joint>
  <link
    name="torso">
    <inertial>
      <origin
        xyz="-0.021861 -0.000071 0.306332"
        rpy="0 0 0" />
      <mass
        value="13.015" />
      <inertia
        ixx="0.65999"
        ixy="0.000345"
        ixz="0.089157"
        iyy="0.623141"
        iyz="-0.000111"
        izz="0.187149" />
    </inertial>
    <visual>
      <origin
        xyz="0 0 0"
        rpy="0 0 0" />
      <geometry>
        <mesh
          filename="torso.STL" />
      </geometry>
      <material
        name="">
        <color
          rgba="0.752941176470588 0.752941176470588 0.752941176470588 1" />
      </material>
    </visual>
    <collision>
      <origin
        xyz="0 0 0"
        rpy="0 0 0" />
      <geometry>
        <mesh
          filename="torso.STL" />
      </geometry>
    </collision>
  </link>
  <link name="IMUlink"/>
  <joint name="IMUfixedjoint" type="fixed">
    <!-- <origin rpy="0 0 0" xyz="0 0 0.725000"/> -->
    <origin rpy="0 0 0" xyz="-0.047 -0.01825 0.21965"/>
    <parent link="torso"/>
    <child link="IMUlink"/>
  </joint>
  <link
    name="Rhip">
    <inertial>
      <origin
        xyz="-0.00466 -0.004924 0.000165"
        rpy="0 0 0" />
      <mass
        value="1.774321" />
      <inertia
        ixx="0.002141"
        ixy="-0.000042"
        ixz="-0.00001"
        iyy="0.002423"
        iyz="0.000001"
        izz="0.002503" />
    </inertial>
    <visual>
      <origin
        xyz="0 0 0"
        rpy="0 0 0" />
      <geometry>
        <mesh
          filename="Rhip.STL" />
      </geometry>
      <material
        name="">
        <color
          rgba="0.752941176470588 0.752941176470588 0.752941176470588 1" />
      </material>
    </visual>
    <collision>
      <origin
        xyz="0 0 0"
        rpy="0 0 0" />
      <geometry>
        <mesh
          filename="Rhip.STL" />
      </geometry>
    </collision>
  </link>
  <joint
    name="rhiproll"
    type="revolute">
    <origin
      xyz="0 -0.0874999999999999 0"
      rpy="0 0 0" />
    <parent
      link="torso" />
    <child
      link="Rhip" />
    <axis
      xyz="1 0 0" />
    <limit effort="500" velocity="3140" lower="-1.57079632679" upper="1.57079632679"/>
  </joint>
  <link
    name="Rfem">
    <inertial>
      <origin
        xyz="0.003266 -0.02494 -0.150289"
        rpy="0 0 0" />
      <mass
        value="2.377365" />
      <inertia
        ixx="0.02402"
        ixy="-0.000426"
        ixz="-0.000616"
        iyy="0.023492"
        iyz="0.001994"
        izz="0.004009" />
    </inertial>
    <visual>
      <origin
        xyz="0 0 0"
        rpy="0 0 0" />
      <geometry>
        <mesh
          filename="Rfem.STL" />
      </geometry>
      <material
        name="">
        <color
          rgba="0.75294 0.75294 0.75294 1" />
      </material>
    </visual>
    <collision>
      <origin
        xyz="0 0 0"
        rpy="0 0 0" />
      <geometry>
        <mesh
          filename="Rfem.STL" />
      </geometry>
    </collision>
  </link>
  <joint
    name="rfempitch"
    type="revolute">
    <origin
      xyz="0 0 0"
      rpy="0 0 0" />
    <parent
      link="Rhip" />
    <child
      link="Rfem" />
    <axis
      xyz="0 -1 0" />
    <limit effort="500" velocity="3140" lower="-1.57079632679" upper="1.57079632679"/>
  </joint>
  <link
    name="Rtib">
    <inertial>
      <origin
        xyz="-0.004172 0.006614 -0.063065"
        rpy="0 0 0" />
      <mass
        value="2.391007" />
      <inertia
        ixx="0.03621"
        ixy="-0.000477"
        ixz="0.001092"
        iyy="0.036273"
        iyz="-0.001773"
        izz="0.003229" />
    </inertial>
    <visual>
      <origin
        xyz="0 0 0"
        rpy="0 0 0" />
      <geometry>
        <mesh
          filename="Rtib.STL" />
      </geometry>
      <material
        name="">
        <color
          rgba="0.752941176470588 0.752941176470588 0.752941176470588 1" />
      </material>
    </visual>
    <collision>
      <origin
        xyz="0 0 0"
        rpy="0 0 0" />
      <geometry>
        <mesh
          filename="Rtib.STL" />
      </geometry>
    </collision>
  </link>
  <joint
    name="rtibpitch"
    type="revolute">
    <origin
      xyz="0 -0.0296000000000004 -0.349999999999999"
      rpy="0 0 0" />
    <parent
      link="Rfem" />
    <child
      link="Rtib" />
    <axis
      xyz="0 -1 0" />
    <limit effort="500" velocity="3140" lower="-1.57079632679" upper="1.57079632679"/>
  </joint>
  <link
    name="Rfoot">
    <inertial>
      <origin
        xyz="0.010766 -0.000149 -0.041817"
        rpy="0 0 0" />
      <mass
        value="0.527463" />
      <inertia
        ixx="0.000262"
        ixy="0"
        ixz="-0.000071"
        iyy="0.000932"
        iyz="0"
        izz="0.000977" />
    </inertial>
    <visual>
      <origin
        xyz="0 0 0"
        rpy="0 0 0" />
      <geometry>
        <mesh
          filename="Rfoot.STL" />
      </geometry>
      <material
        name="">
        <color
          rgba="0.752941176470588 0.752941176470588 0.752941176470588 1" />
      </material>
    </visual>
    <collision>
      <origin
        xyz="0 0 0"
        rpy="0 0 0" />
      <geometry>
        <mesh
          filename="Rfoot.STL" />
      </geometry>
    </collision>
  </link>
  <joint
    name="rfootpitch"
    type="revolute">
    <origin
      xyz="0 0.00674999999999973 -0.35"
      rpy="0 0 0" />
    <parent
      link="Rtib" />
    <child
      link="Rfoot" />
    <axis
      xyz="0 -1 0" />
    <limit effort="500" velocity="3140" lower="-1.57079632679" upper="1.57079632679"/>
  </joint>
  <link
    name="Lhip">
    <inertial>
      <origin
        xyz="-0.00466 0.004924 0.000165"
        rpy="0 0 0" />
      <mass
        value="1.774321" />
      <inertia
        ixx="0.002141"
        ixy="0.000042"
        ixz="-0.00001"
        iyy="0.002423"
        iyz="0.000001"
        izz="0.002503" />
    </inertial>
    <visual>
      <origin
        xyz="0 0 0"
        rpy="0 0 0" />
      <geometry>
        <mesh
          filename="Lhip.STL" />
      </geometry>
      <material
        name="">
        <color
          rgba="0.752941176470588 0.752941176470588 0.752941176470588 1" />
      </material>
    </visual>
    <collision>
      <origin
        xyz="0 0 0"
        rpy="0 0 0" />
      <geometry>
        <mesh
          filename="Lhip.STL" />
      </geometry>
    </collision>
  </link>
  <joint
    name="lhiproll"
    type="revolute">
    <origin
      xyz="0 0.0867792575780178 0"
      rpy="0 0 0" />
    <parent
      link="torso" />
    <child
      link="Lhip" />
    <axis
      xyz="1 0 0" />
    <limit effort="500" velocity="3140" lower="-1.57079632679" upper="1.57079632679"/>
  </joint>
  <link
    name="Lfem">
    <inertial>
      <origin
        xyz="0.003266 0.02494 -0.150289"
        rpy="0 0 0" />
      <mass
        value="2.377365" />
      <inertia
        ixx="0.02402"
        ixy="0.000426"
        ixz="-0.000616"
        iyy="0.023492"
        iyz="-0.001994"
        izz="0.004009" />
    </inertial>
    <visual>
      <origin
        xyz="0 0 0"
        rpy="0 0 0" />
      <geometry>
        <mesh
          filename="Lfem.STL" />
      </geometry>
      <material
        name="">
        <color
          rgba="0.75294 0.75294 0.75294 1" />
      </material>
    </visual>
    <collision>
      <origin
        xyz="0 0 0"
        rpy="0 0 0" />
      <geometry>
        <mesh
          filename="Lfem.STL" />
      </geometry>
    </collision>
  </link>
  <joint
    name="lfempitch"
    type="revolute">
    <origin
      xyz="0 0 0"
      rpy="0 0 0" />
    <parent
      link="Lhip" />
    <child
      link="Lfem" />
    <axis
      xyz="0 -1 0" />
    <limit effort="500" velocity="3140" lower="-1.57079632679" upper="1.57079632679"/>
  </joint>
  <link
    name="Ltib">
    <inertial>
      <origin
        xyz="-0.004172 -0.006614 -0.063065"
        rpy="0 0 0" />
      <mass
        value="2.391007" />
      <inertia
        ixx="0.03621"
        ixy="0.000477"
        ixz="0.001092"
        iyy="0.036273"
        iyz="0.001773"
        izz="0.003229" />
    </inertial>
    <visual>
      <origin
        xyz="0 0 0"
        rpy="0 0 0" />
      <geometry>
        <mesh
          filename="Ltib.STL" />
      </geometry>
      <material
        name="">
        <color
          rgba="0.75294 0.75294 0.75294 1" />
      </material>
    </visual>
    <collision>
      <origin
        xyz="0 0 0"
        rpy="0 0 0" />
      <geometry>
        <mesh
          filename="Ltib.STL" />
      </geometry>
    </collision>
  </link>
  <joint
    name="ltibpitch"
    type="revolute">
    <origin
      xyz="0 0.0295970170207031 -0.349999559364049"
      rpy="0 0 0" />
    <parent
      link="Lfem" />
    <child
      link="Ltib" />
    <axis
      xyz="0.0 -1 0.0" />
    <limit effort="500" velocity="3140" lower="-1.57079632679" upper="1.57079632679"/>
  </joint>
  <link
    name="Lfoot">
    <inertial>
      <origin
        xyz="0.010766 0.000149 -0.041817"
        rpy="0 0 0" />
      <mass
        value="0.527463" />
      <inertia
        ixx="0.000262"
        ixy="0"
        ixz="-0.000071"
        iyy="0.000932"
        iyz="0"
        izz="0.000977" />
    </inertial>
    <visual>
      <origin
        xyz="0 0 0"
        rpy="0 0 0" />
      <geometry>
        <mesh
          filename="Lfoot.STL" />
      </geometry>
      <material
        name="">
        <color
          rgba="0.75294 0.75294 0.75294 1" />
      </material>
    </visual>
    <collision>
      <origin
        xyz="0 0 0"
        rpy="0 0 0" />
      <geometry>
        <mesh
          filename="Lfoot.STL" />
      </geometry>
    </collision>
  </link>
  <joint
    name="lfootpitch"
    type="revolute">
    <origin
      xyz="-2.9334E-05 -0.0067405 -0.35"
      rpy="0 0 0" />
    <parent
      link="Ltib" />
    <child
      link="Lfoot" />
    <axis
      xyz="0.0 -1 0.0" />
    <limit effort="500" velocity="3140" lower="-1.57079632679" upper="1.57079632679"/>
  </joint>
  <link
    name="Rshoulder">
    <inertial>
      <origin
        xyz="0.010946 -0.049052 -0.165294"
        rpy="0 0 0" />
      <mass
        value="4.101086" />
      <inertia
        ixx="0.138641"
        ixy="-0.00041"
        ixz="-0.017313"
        iyy="0.138945"
        iyz="0.008685"
        izz="0.012567" />
    </inertial>
    <visual>
      <origin
        xyz="0 0 0"
        rpy="0 0 0" />
      <geometry>
        <mesh
          filename="Rshoulder.STL" />
      </geometry>
      <material
        name="">
        <color
          rgba="0.79216 0.81961 0.93333 1" />
      </material>
    </visual>
    <collision>
      <origin
        xyz="0 0 0"
        rpy="0 0 0" />
      <geometry>
        <mesh
          filename="Rshoulder.STL" />
      </geometry>
    </collision>
  </link>
  <joint
    name="rshoulderpitch"
    type="revolute">
    <origin
      xyz="0 -0.1798 0.4735"
      rpy="0 0 0" />
    <parent
      link="torso" />
    <child
      link="Rshoulder" />
    <axis
      xyz="0 -1 0" />
    <limit effort="500" velocity="3140" lower="-1.57079632679" upper="1.57079632679"/>
  </joint>
  <link
    name="Lshoulder">
    <inertial>
      <origin
        xyz="0.010946 0.049052 -0.165294"
        rpy="0 0 0" />
      <mass
        value="4.101086" />
      <inertia
        ixx="0.138641"
        ixy="0.00041"
        ixz="-0.017313"
        iyy="0.138945"
        iyz="-0.008685"
        izz="0.012567" />
    </inertial>
    <visual>
      <origin
        xyz="0 0 0"
        rpy="0 0 0" />
      <geometry>
        <mesh
          filename="Lshoulder.STL" />
      </geometry>
      <material
        name="">
        <color
          rgba="0.792156862745098 0.819607843137255 0.933333333333333 1" />
      </material>
    </visual>
    <collision>
      <origin
        xyz="0 0 0"
        rpy="0 0 0" />
      <geometry>
        <mesh
          filename="Lshoulder.STL" />
      </geometry>
    </collision>
  </link>
  <joint
    name="lshoulderpitch"
    type="revolute">
    <origin
      xyz="0 0.1798 0.4735"
      rpy="0 0 0" />
    <parent
      link="torso" />
    <child
      link="Lshoulder" />
    <axis
      xyz="0 -1 0" />
    <limit effort="500" velocity="3140" lower="-1.57079632679" upper="1.57079632679"/>
  </joint>
</robot>
<mujoco>
      <compiler 
      meshdir="/" 
      balanceinertia="true" 
      discardvisual="false" />
</mujoco>
